Wed Dec 19 11:28:57 CET 2018 : Servidor de red Apache Derby: Se ha iniciado 10.11.1.2 - (1629631) y está listo para aceptar las conexiones en el puerto 1527
----------------------------------------------------------------
Wed Dec 19 11:29:01 CET 2018:
 Iniciando instancia a816c00e-0167-c602-d3bb-00005c63b51b de Derby, versión The Apache Software Foundation - Apache Derby - 10.11.1.2 - (1629631): 
en el directorio de base de datos C:\Users\Fiti\Desktop\recuperacionJAVA\recuperacionJava\recuperacionJava\recuperacion con el cargador de clases sun.misc.Launcher$AppClassLoader@6f94fa3e
Cargado desde file:/C:/Program%20Files/Java/jdk1.8.0_111/db/lib/derby.jar
java.vendor=Oracle Corporation
java.runtime.version=1.8.0_111-b14
user.dir=C:\Program Files\Java\jdk1.8.0_111\db
os.name=Windows 10
os.arch=amd64
os.version=10.0
derby.system.home=C:\Users\Fiti\Desktop\recuperacionJAVA\recuperacionJava\recuperacionJava
Cargador de clases de base de datos iniciado - derby.database.classpath=''
----------------------------------------------------------------
Wed Dec 19 11:29:01 CET 2018:
Cerrando la instancia a816c00e-0167-c602-d3bb-00005c63b51b en el directorio de base de datos C:\Users\Fiti\Desktop\recuperacionJAVA\recuperacionJava\recuperacionJava\recuperacion con cargador de clases sun.misc.Launcher$AppClassLoader@6f94fa3e
Wed Dec 19 11:29:02 CET 2018 Thread[DRDAConnThread_2,5,main] (DATABASE = recuperacion), (DRDAID = {2}), Cierre de la base de datos 'recuperacion'.
----------------------------------------------------------------
Wed Dec 19 11:29:13 CET 2018:
 Iniciando instancia a65c80ac-0167-c602-d3bb-00005c63b51b de Derby, versión The Apache Software Foundation - Apache Derby - 10.11.1.2 - (1629631): 
en el directorio de base de datos C:\Users\Fiti\Desktop\recuperacionJAVA\recuperacionJava\recuperacionJava\recuperacion con el cargador de clases sun.misc.Launcher$AppClassLoader@6f94fa3e
Cargado desde file:/C:/Program%20Files/Java/jdk1.8.0_111/db/lib/derby.jar
java.vendor=Oracle Corporation
java.runtime.version=1.8.0_111-b14
user.dir=C:\Program Files\Java\jdk1.8.0_111\db
os.name=Windows 10
os.arch=amd64
os.version=10.0
derby.system.home=C:\Users\Fiti\Desktop\recuperacionJAVA\recuperacionJava\recuperacionJava
Cargador de clases de base de datos iniciado - derby.database.classpath=''
Wed Dec 19 14:01:47 CET 2018 Thread[DRDAConnThread_3,5,main] (XID = 428), (SESSIONID = 4), (DATABASE = recuperacion), (DRDAID = {5}), Cleanup action starting
java.sql.SQLNonTransientConnectionException: Se ha producido un fallo de autenticación de conexión. Motivo: Autenticación no válida..
	at org.apache.derby.impl.jdbc.SQLExceptionFactory.getSQLException(Unknown Source)
	at org.apache.derby.impl.jdbc.SQLExceptionFactory.getSQLException(Unknown Source)
	at org.apache.derby.impl.jdbc.Util.generateCsSQLException(Unknown Source)
	at org.apache.derby.impl.jdbc.Util.generateCsSQLException(Unknown Source)
	at org.apache.derby.impl.jdbc.EmbedConnection.newSQLException(Unknown Source)
	at org.apache.derby.impl.jdbc.EmbedConnection.checkUserCredentials(Unknown Source)
	at org.apache.derby.impl.jdbc.EmbedConnection.<init>(Unknown Source)
	at org.apache.derby.jdbc.InternalDriver.getNewEmbedConnection(Unknown Source)
	at org.apache.derby.jdbc.InternalDriver.connect(Unknown Source)
	at org.apache.derby.jdbc.InternalDriver.connect(Unknown Source)
	at org.apache.derby.jdbc.EmbeddedDriver.connect(Unknown Source)
	at org.apache.derby.impl.drda.Database.makeConnection(Unknown Source)
	at org.apache.derby.impl.drda.DRDAConnThread.getConnFromDatabaseName(Unknown Source)
	at org.apache.derby.impl.drda.DRDAConnThread.verifyUserIdPassword(Unknown Source)
	at org.apache.derby.impl.drda.DRDAConnThread.parseSECCHK(Unknown Source)
	at org.apache.derby.impl.drda.DRDAConnThread.parseDRDAConnection(Unknown Source)
	at org.apache.derby.impl.drda.DRDAConnThread.processCommands(Unknown Source)
	at org.apache.derby.impl.drda.DRDAConnThread.run(Unknown Source)
Caused by: ERROR 08004: Se ha producido un fallo de autenticación de conexión. Motivo: Autenticación no válida..
	at org.apache.derby.iapi.error.StandardException.newException(Unknown Source)
	at org.apache.derby.impl.jdbc.SQLExceptionFactory.wrapArgsForTransportAcrossDRDA(Unknown Source)
	... 18 more
============= begin nested exception, level (1) ===========
ERROR 08004: Se ha producido un fallo de autenticación de conexión. Motivo: Autenticación no válida..
	at org.apache.derby.iapi.error.StandardException.newException(Unknown Source)
	at org.apache.derby.impl.jdbc.SQLExceptionFactory.wrapArgsForTransportAcrossDRDA(Unknown Source)
	at org.apache.derby.impl.jdbc.SQLExceptionFactory.getSQLException(Unknown Source)
	at org.apache.derby.impl.jdbc.SQLExceptionFactory.getSQLException(Unknown Source)
	at org.apache.derby.impl.jdbc.Util.generateCsSQLException(Unknown Source)
	at org.apache.derby.impl.jdbc.Util.generateCsSQLException(Unknown Source)
	at org.apache.derby.impl.jdbc.EmbedConnection.newSQLException(Unknown Source)
	at org.apache.derby.impl.jdbc.EmbedConnection.checkUserCredentials(Unknown Source)
	at org.apache.derby.impl.jdbc.EmbedConnection.<init>(Unknown Source)
	at org.apache.derby.jdbc.InternalDriver.getNewEmbedConnection(Unknown Source)
	at org.apache.derby.jdbc.InternalDriver.connect(Unknown Source)
	at org.apache.derby.jdbc.InternalDriver.connect(Unknown Source)
	at org.apache.derby.jdbc.EmbeddedDriver.connect(Unknown Source)
	at org.apache.derby.impl.drda.Database.makeConnection(Unknown Source)
	at org.apache.derby.impl.drda.DRDAConnThread.getConnFromDatabaseName(Unknown Source)
	at org.apache.derby.impl.drda.DRDAConnThread.verifyUserIdPassword(Unknown Source)
	at org.apache.derby.impl.drda.DRDAConnThread.parseSECCHK(Unknown Source)
	at org.apache.derby.impl.drda.DRDAConnThread.parseDRDAConnection(Unknown Source)
	at org.apache.derby.impl.drda.DRDAConnThread.processCommands(Unknown Source)
	at org.apache.derby.impl.drda.DRDAConnThread.run(Unknown Source)
============= end nested exception, level (1) ===========
Cleanup action completed
Wed Dec 19 14:01:47 CET 2018 Thread[DRDAConnThread_3,5,main] (DATABASE = recuperacion), (DRDAID = {5}), Se ha producido un fallo de autenticación de conexión. Motivo: Autenticación no válida..
